-----------------------------------Registro de errores - 2025-08-18 20:37:57-----------------------------------

ðŸš¨Traceback (most recent call last):
  File "C:\mha\scripts_sobrepeso\ejecutar_procesar_tpm.py", line 13, in <module>
    subprocess.run(["python", ruta], check=True)
    ~~~~~~~~~~~~~~^^^^^^^^^^^^^^^^^^^^^^^^^^^^^^
  File "C:\Users\CMMHERRERA\AppData\Local\Programs\Python\Python313\Lib\subprocess.py", line 579, in run
    raise CalledProcessError(retcode, process.args,
                             output=stdout, stderr=stderr)
subprocess.CalledProcessError: Command '['python', 'C:\\mha\\scripts_sobrepeso\\informes_py\\Script_Molido_Bog_v2.py']' returned non-zero exit status 1.
